Workbook

Sheet アイデア集
A1: テーマ | B1: テーマ名 | C1: 一言で | D1: 代表例 | E1: 標準機能との違い | F1: 独自アプローチのヒント（抜粋） | G1: 自作の難しさ | H1: 関連LISP（件） | I1: 詳しい解説
A2: T01 | B2: 操作に反応して自動処理（リアクター） | C2: コマンドや保存を見張り、決まった処理を自動実行 | D2: Layer Director（英語圏）、LATT（ヨーロッパ）、Automatic Block Break（英語圏）、LISP Ánh xạ giá trị đối tượng（ベトナム・東南アジア）、修正文字自動赤化（日本） | E2: 標準は一部図形の画層固定のみ。任意の操作に割り込む仕組みはない | F2: 保存時に社内規定違反（画層名・色）を見つけて一覧で警告する見張り番 | G2: ★★★ | H2: 40 | I2: catalog/アイデア集/T01_操作に反応して自動処理（リアクター）.md
A3: T02 | B3: 図面を開かずに一括処理 | C3: 多数の図面を開かずに裏で調べたり書き換えたりする | D3: 批量制作目录—不开图提取块属性（中国語圏）、DBXscanBlocks（英語圏）、ODBX_LIB（ヨーロッパ）、cpdf.lsp（ベトナム・東南アジア）、ObjectDBX Wrapper（英語圏） | E3: 標準は覗く・抽出する程度。開かずに一括で書き換える機能はない | F3: 図枠属性とファイル名・更新日を並べた図面台帳を自動作成し食い違いに印を付ける | G3: ★★★ | H3: 53 | I3: catalog/アイデア集/T02_図面を開かずに一括処理.md
A4: T03 | B4: 複数図面へのスクリプト一括実行 | C4: フォルダ内の図面に同じ作業や自作LISPを自動で繰り返す | D4: CAD Batch Runner（英語圏）、Batch Find & Replace Text（英語圏）、Batch DWG-Commander（日本）、SCRIPTOR（ヨーロッパ）、块更新（中国語圏） | E4: SCRIPTはあるが複数図面用の手順は自作。LISPを選んで全図面に適用する画面はない | F4: 処理前後の変化数と警告を図面ごとに表にし、確認すべき図面だけを示す | G4: ★★ | H4: 75 | I4: catalog/アイデア集/T03_複数図面へのスクリプト一括実行.md
A5: T04 | B5: 図枠の自動認識→一括印刷 | C5: モデル空間の図枠を自動で見つけて一括印刷・PDF化 | D5: 批量打印-邱枫版（中国語圏）、PlotDWGarr ほか（英語圏）、FrameFinder（ロシア語圏）、ABP-Batch Plot（ベトナム・東南アジア）、export_dwf_main（GitHub） | E5: 標準はレイアウト単位の一括印刷のみ。モデル内の図枠検出や用紙自動判定はない | F5: 図枠の図番属性を読み取りPDFファイル名を「図番_図名」にして一括出力 | G5: ★★ | H5: 139 | I5: catalog/アイデア集/T04_図枠の自動認識→一括印刷.md
A6: T05 | B6: 図枠からレイアウト・ビューポートを自動作成 | C6: 図枠1つごとにレイアウトとビューポートを自動作成 | D6: Auto layout LISP（英語圏）、AUTOLAMINAS（その他の地域）、FrameFinder（ロシア語圏）、Ghép khung bản đồ（ベトナム・東南アジア）、VPTOMODEL（日本） | E6: 標準は手作業で1枚ずつ作成。図枠からの量産や図番によるレイアウト名付けはない | F6: 図枠を動かし増やしても既存レイアウトを消さず差分だけ更新する | G6: ★★ | H6: 175 | I6: catalog/アイデア集/T05_図枠からレイアウト・ビューポートを自動作成.md
A7: T06 | B7: 図枠の属性を自動更新 | C7: 図枠の図番・日付・頁番号を自動記入し目録も作る | D7: RenameLOA reactor（英語圏）、@lisp工程管理（中国語圏）、Update Titleblock Attributes（英語圏）、Tạo Danh mục bản vẽ tự động（ベトナム・東南アジア）、NUMERAR_PLANOS（その他の地域） | E7: 標準は属性の個別編集とフィールド程度。Excelからの一括流し込みや規則的な再採番はない | F7: 図面目録のExcelを元データにして図枠へ流し込み、図面側の変更は色付きで書き戻す | G7: ★★ | H7: 89 | I7: catalog/アイデア集/T06_図枠の属性を自動更新.md
A8: T07 | B8: 検図：寸法値の手入力上書きを検出 | C8: 手で書き換えた寸法値を見つけて色で知らせる | D8: DIMPOLICE（日本）、OverDimCol（英語圏）、DIMLFAC可視化（ロシア語圏）、FakeDims（ベトナム・東南アジア）、尺寸原值（中国語圏） | E8: 標準はプロパティで1件ずつ確認のみ。自動の色付け・実測値との差の表示は無い | F8: 書かれた値と実測値の差の大きさで3段階に色分けし、直す優先順位を見せる | G8: ★ | H8: 53 | I8: catalog/アイデア集/T07_検図：寸法値の手入力上書きを検出.md
A9: T08 | B9: 検図：わずかなずれ・隙間・重なりを検出 | C9: 見えない小さな隙間・傾き・重なりを探して印を付ける | D9: ZureMikke（日本）、TxtOverlap（英語圏）、Gaps（英語圏）、定位压线字（中国語圏）、EL-CHECK（ロシア語圏） | E9: 標準はOVERKILL・JOINで直すのみ。隙間や傾きの場所を見つけて示す機能は無い | F9: 隙間・傾き・重なり・開いた線を色分けし、1回で検図レポート化。許容値は図面尺度から自動決定 | G9: ★★ | H9: 81 | I9: catalog/アイデア集/T08_検図：わずかなずれ・隙間・重なりを検出.md
A10: T09 | B10: 新旧図面の差分比較・雲マーク | C10: 修正前後を比べ、変わった所に自動で雲マークを付ける | D10: DiffCheck（GitHub）、阿甘对图器（中国語圏）、修正文字自動赤化（日本）、2図面比較ツール（ベトナム・東南アジア）、LogBook（英語圏） | E10: 標準DWGCOMPAREは図面単位の比較。図面内の範囲比較や改訂欄記入は不可 | F10: 追加・削除・移動・文字変更で雲の色を分け、改訂△と改訂欄への記入まで自動化する | G10: ★★★ | H10: 33 | I10: catalog/アイデア集/T09_新旧図面の差分比較・雲マーク.md
A11: T10 | B11: 図面の健全性チェック・お掃除 | C11: 図面にたまったゴミや不具合を調べて一括で掃除する | D11: DrawingHealthScore（GitHub）、CAD批量清理（中国語圏）、DBXremSL（英語圏）、Finalizer（日本）、odbx_purge（ヨーロッパ） | E11: 標準はPURGE・AUDIT等を1図面ずつ。開かずに一括掃除や状態の点数化は無い | F11: 掃除前後のサイズ・画層数などを比べたビフォーアフター表を出し、効果を見える化する | G11: ★★ | H11: 154 | I11: catalog/アイデア集/T10_図面の健全性チェック・お掃除.md
A12: T11 | B12: 文字の重なりを自動で避ける・整列 | C12: 重なった文字を自動でずらし、きれいに並べる | D12: 文字避让（中国語圏）、MLeaderSmartAlign（GitHub）、TxtOverlap（英語圏）、JustifyTextAuto（日本）、Overlapping texts（ヨーロッパ） | E12: 標準はTEXTALIGN等の整列のみ。重なった文字を見つけて自動で逃がす機能は無い | F12: 文字の種類ごとに優先度を決め、重要な文字は動かさず他を逃がす。印刷時の離れ量で判定 | G12: ★★★ | H12: 136 | I12: catalog/アイデア集/T11_文字の重なりを自動で避ける・整列.md
A13: T12 | B13: 文字の一括検索・置換 | C13: 複数図面や大量の文字をルールに沿って一括で書き換える | D13: Batch Find & Replace Text（英語圏）、図面対訳翻訳LISP（ベトナム・東南アジア）、QE剪贴板批量替换（中国語圏）、odbx_subst（ヨーロッパ）、交点へクリップボード一括貼付（日本） | E13: 標準FINDは開いた図面のみ。複数図面・正規表現・Excel表による置換は不可 | F13: 全角半角・㎜とmm・長音記号など日本語の表記ゆれを一括で統一するモードを作る | G13: ★★ | H13: 509 | I13: catalog/アイデア集/T12_文字の一括検索・置換.md
... A31: T30 | B31: AI・OCR・翻訳など新技術との連携 | C31: AI・OCR・翻訳・地図サービスをAutoCADから呼び出す | D31: Lisp dịch thuật bản vẽ song ngữ（ベトナム・東南アジア）、PDFOCRTEXT（中国語圏）、AIGC（中国語圏）、JSONout/JSONin（英語圏）、拡張エンティティ属性付与（日本） | E31: 標準はPDF取込とSHX文字認識程度で、一括翻訳・任意AIでの図面チェックは不可 | F31: 図面文字・寸法をJSON化してAIに表記ゆれや寸法の食い違いをチェックさせる | G31: ★★★ | H31: 103 | I31: catalog/アイデア集/T30_AI・OCR・翻訳など新技術との連携.md
A33: 使い方：「総合一覧」シートの「テーマ」列で T15 などと絞り込むと、そのテーマの関連LISPがすべて表示されます（ダウンロード対象の選定に使えます）。

Sheet 総合一覧
A1: 順位 | B1: 地域 | C1: 分野 | D1: テーマ | E1: テーマ名 | F1: コマンド | G1: 名前 | H1: 何をするツールか | I1: 非代替性 | J1: 斬新さ | K1: 時短効果 | L1: 汎用性 | M1: 合計 | N1: 評価メモ | O1: 作者 | P1: サイト | Q1: リンク | R1: 入手方法（見込み） | S1: 形式（見込み） | T1: 同じツールの別掲載 | U1: ID
A2: =RANK(M2,$M$2:$M$6943) | B2: 英語圏 | C2: 画層 | D2: T18,T01 | E2: 画層の自動振り分け・標準化、操作に反応して自動処理（リアクター） | F2: LDON / LDOFF | G2: Layer Director | H2: コマンド毎に画層を自動切替 | I2: 21 | J2: 23 | K2: 17 | L2: 20 | M2: =SUM(I2:L2) | N2: コマンド毎に画層自動切替 | O2: Lee Mac | P2: Lee Mac Programming | Q2: 開く | R2: 配布ページからダウンロード | S2: ソース | U2: W1
A3: =RANK(M3,$M$2:$M$6943) | B3: GitHub | C3: 外部参照・図面管理・一括処理 | D3: T09 | E3: 新旧図面の差分比較・雲マーク | F3: DFC / DiffCheck | G3: DiffCheck | H3: 新旧範囲を自動位置合わせし変更箇所に雲マーク | I3: 24 | J3: 22 | K3: 18 | L3: 16 | M3: =SUM(I3:L3) | N3: 新旧差分に自動雲マーク | O3: beastt1992 | P3: GitHub: beastt1992/DiffCheck | Q3: 開く | R3: GitHub（一括取得可） | S3: ソース | U3: W2
A4: =RANK(M4,$M$2:$M$6943) | B4: 中国語圏 | C4: 外部参照・図面管理・一括処理 | D4: T28 | E4: 作業環境の保存・復元 | F4: 上班/下班 | G4: 会话管理 (@lisp会话) | H4: 開いている図面群を保存し翌日一括再開 | I4: 22 | J4: 20 | K4: 17 | L4: 21 | M4: =SUM(I4:L4) | N4: 作業セッション保存が秀逸 | O4: VitalGG | P4: @lisp 应用云 | Q4: 開く | R4: 配布ページからダウンロード | S4: ソース（GitHubにも公開） | U4: W3
A5: =RANK(M5,$M$2:$M$6943) | B5: 中国語圏 | C5: 印刷・レイアウト・図枠 | D5: T04 | E5: 図枠の自動認識→一括印刷 | F5: 批量打印 | G5: 批量打印-邱枫版 (Batchplot) | H5: 1図面多図枠を自動判定し一括印刷・分図 | I5: 20 | J5: 15 | K5: 23 | L5: 22 | M5: =SUM(I5:L5) | N5: 中国で最も普及した一括印刷 | O5: 邱枫 | P5: @lisp 应用云 | Q5: 開く | R5: 配布ページからダウンロード | S5: ソース（GitHubにも公開） | U5: W4
A6: =RANK(M6,$M$2:$M$6943) | B6: 中国語圏 | C6: 印刷・レイアウト・図枠 | D6: T04 | E6: 図枠の自動認識→一括印刷 | F6: BatchPlot | G6: 批量打印程序v3.6.1 (秋枫版改) | H6: 図枠を自動認識し1図面多図枠を一括印刷 | I6: 20 | J6: 15 | K6: 23 | L6: 22 | M6: =SUM(I6:L6) | N6: 中国標準の一括印刷 | O6: ludaweb/秋枫 | P6: 明经CAD社区 | Q6: 開く | R6: フォーラム添付（ログインが必要な場合あり） | S6: 不明 | U6: W5
A7: =RANK(M7,$M$2:$M$6943) | B7: 中国語圏 | C7: 印刷・レイアウト・図枠 | D7: T04 | E7: 図枠の自動認識→一括印刷 | F7: AI识别图框/批打输出 | G7: 智能识别图框批量打印 (@打印输出) | H7: 図枠をPL/線/ブロックから識別し一括印刷 | I7: 20 | J7: 17 | K7: 22 | L7: 21 | M7: =SUM(I7:L7) | N7: 図枠自動認識の一括印刷 | O7: VitalGG | P7: @lisp 应用云 | Q7: 開く | R7: 配布ページからダウンロード | S7: ソース（GitHubにも公開） | U7: W6
A8: =RANK(M8,$M$2:$M$6943) | B8: GitHub | C8: 外部参照・図面管理・一括処理 | D8: T10 | E8: 図面の健全性チェック・お掃除 | F8: DHS / DHSFIX | G8: DrawingHealthScore | H8: 図面の健全度を100点評価し一括修正 | I8: 22 | J8: 21 | K8: 17 | L8: 18 | M8: =SUM(I8:L8) | N8: 図面健全度スコア化が斬新 | O8: beastt1992 | P8: GitHub: beastt1992/DrawingHealthScore | Q8: 開く | R8: GitHub（一括取得可） | S8: ソース | U8: W7
A9: =RANK(M9,$M$2:$M$6943) | B9: 英語圏 | C9: 画層 | D9: T18,T01 | E9: 画層の自動振り分け・標準化、操作に反応して自動処理（リアクター） | F9: FLAY | G9: FLay | H9: 作図時に指定画層へ自動振分け | I9: 20 | J9: 19 | K9: 18 | L9: 21 | M9: =SUM(I9:L9) | N9: 作図時自動画層振分け | O9: CAD Studio | P9: CAD Forum | Q9: 開く | R9: 配布ページからダウンロード | S9: ソース/暗号化（.vlx）混在 | U9: W8
A10: =RANK(M10,$M$2:$M$6943) | B10: 中国語圏 | C10: 文字・テキスト | D10: T11 | E10: 文字の重なりを自動で避ける・整列 | F10: 文字避让 | G10: 文字避让 (@lisp文本) | H10: 重なった単線文字を自動で逃がし配置 | I10: 22 | J10: 20 | K10: 17 | L10: 18 | M10: =SUM(I10:L10) | N10: 重なり自動回避は独自 | O10: VitalGG | P10: @lisp 应用云 | Q10: 開く | R10: 配布ページからダウンロード | S10: ソース（GitHubにも公開） | U10: W9
A11: =RANK(M11,$M$2:$M$6943) | B11: 英語圏 | C11: 文字・テキスト | D11: T15 | E11: 連番の自動記入 | F11: NumInc | G11: Incremental Numbering Suite | H11: 連番文字・属性を配置 | I11: 18 | J11: 15 | K11: 21 | L11: 22 | M11: =SUM(I11:L11) | N11: 連番配置の決定版、多機能 | O11: Lee Mac | P11: Lee Mac Programming | Q11: 開く | R11: 配布ページからダウンロード | S11: ソース | U11: W10
A12: =RANK(M12,$M$2:$M$6943) | B12: 英語圏 | C12: ハッチ・面積・長さ集計 | D12: T13,T16 | E12: 図形と数値の連動（フィールド・面積表）、数量拾い・集計表 | F12: AOL | G12: Area Object Link (AOL) | H12: 面積・周長を属性にリンクし集計表 | I12: 20 | J12: 19 | K12: 20 | L12: 16 | M12: =SUM(I12:L12) | N12: 面積を属性リンクし集計表 | O12: @The Office | P12: Autodesk App Store | Q12: 開く | R12: アプリストア経由（Autodeskアカウントが必要） | S12: 暗号化・インストーラ | U12: W11
A13: =RANK(M13,$M$2:$M$6943) | B13: 英語圏 | C13: 外部参照・図面管理・一括処理 | D13: T03 | E13: 複数図面へのスクリプト一括実行 | F13: - | G13: CAD Batch Runner | H13: 複数図面にスクリプト/LISPを一括実行 | I13: 18 | J13: 13 | K13: 22 | L13: 22 | M13: =SUM(I13:L13) | N13: 複数図面に一括実行 | O13: ESurveying Softech | P13: eSurveying | Q13: 開く | R13: 配布ページからダウンロード | S13: 暗号化（.fas）が中心 | U13: W12
... A45: =RANK(M45,$M$2:$M$6943) | B45: 英語圏 | C45: 外部参照・図面管理・一括処理 | D45: T14,T03 | E45: 属性の抽出・一括編集・Excelとの往復、複数図面へのスクリプト一括実行 | F45: batte | G45: Batch Attribute Editor | H45: 複数図面の属性を一括編集 | I45: 19 | J45: 13 | K45: 20 | L45: 18 | M45: =SUM(I45:L45) | N45: 図面を開かず属性一括編集 | O45: Lee Mac | P45: Lee Mac Programming | Q45: 開く | R45: 配布ページからダウンロード | S45: ソース | U45: W44
A46: =RANK(M46,$M$2:$M$6943) | B46: 英語圏 | C46: 文字・テキスト | D46: T15 | E46: 連番の自動記入 | F46: NUMINC | G46: Incremental Numbering (NumInc) | H46: 連番テキスト・ブロックを配置 | I46: 16 | J46: 14 | K46: 19 | L46: 21 | M46: =SUM(I46:L46) | N46: 連番文字・ブロック両対応 | O46: MEP WORK | P46: MEP WORK | Q46: 開く | R46: 配布ページからダウンロード | S46: 不明 | T46: MEP Details | U46: W45
A47: =RANK(M47,$M$2:$M$6943) | B47: ベトナム・東南アジア | C47: 文字・テキスト | D47: T30,T12 | E47: AI・OCR・翻訳など新技術との連携、文字の一括検索・置換 | F47: AIT | G47: Lisp dịch thuật bản vẽ song ngữ AutoCAD | H47: AIで図面文字を対訳翻訳（有料） | I47: 21 | J47: 19 | K47: 16 | L47: 14 | M47: =SUM(I47:L47) | N47: AIで図面を対訳翻訳 | O47: AJS / AutoLISP Thật là đơn giản | P47: lisp.vn (AutoLISP Reviewer) | Q47: 開く | R47: 有料 | S47: 不明 | U47: W46
A48: =RANK(M48,$M$2:$M$6943) | B48: 中国語圏 | C48: 作図 | D48: その他 | E48: その他 | F48: S | G48: 填充图案拉伸6.0 | H48: ハッチ境界ごと追従させるSTRETCH代替 | I48: 19 | J48: 16 | K48: 17 | L48: 18 | M48: =SUM(I48:L48) | N48: ハッチも伸びるSTRETCH | O48: 陈伟 | P48: 明经CAD社区 | Q48: 開く | R48: フォーラム添付（ログインが必要な場合あり） | S48: 不明 | U48: W47
A49: =RANK(M49,$M$2:$M$6943) | B49: 中国語圏 | C49: 文字・テキスト | D49: T08,T11 | E49: 検図：わずかなずれ・隙間・重なりを検出、文字の重なりを自動で避ける・整列 | F49: 定位压线字 | G49: 定位压线字 (@lisp文本) | H49: 線と重なっている文字を強調表示 | I49: 21 | J49: 18 | K49: 13 | L49: 18 | M49: =SUM(I49:L49) | N49: 図面チェック用に有用 | O49: VitalGG | P49: @lisp 应用云 | Q49: 開く | R49: 配布ページからダウンロード | S49: ソース（GitHubにも公開） | U49: W48
A50: =RANK(M50,$M$2:$M$6943) | B50: 中国語圏 | C50: 作図 | D50: その他 | E50: その他 | F50: S | G50: 带填充拉伸_v8.6（记忆拉伸） | H50: ハッチ連動ストレッチ・前回値記憶 | I50: 19 | J50: 16 | K50: 17 | L50: 18 | M50: =SUM(I50:L50) | N50: ハッチ連動STRETCH | O50: kucha007 | P50: 明经CAD社区 | Q50: 開く | R50: フォーラム添付（ログインが必要な場合あり） | S50: 不明 | U50: W49
A51: =RANK(M51,$M$2:$M$6943) | B51: 中国語圏 | C51: 印刷・レイアウト・図枠 | D51: T02,T06,T14 | E51: 図面を開かずに一括処理、図枠の属性を自動更新、属性の抽出・一括編集・Excelとの往復 | F51: ZZML | G51: 批量制作目录—不开图提取块属性 | H51: 図面を開かずに図枠属性を抽出し目録化 | I51: 20 | J51: 14 | K51: 20 | L51: 16 | M51: =SUM(I51:L51) | N51: 非オープン一括目録 | O51: kucha007 | P51: 明经CAD社区 | Q51: 開く | R51: フォーラム添付（ログインが必要な場合あり） | S51: 不明 | U51: W50
A52: =RANK(M52,$M$2:$M$6943) | B52: 英語圏 | C52: ハッチ・面積・長さ集計 | D52: T13 | E52: 図形と数値の連動（フィールド・面積表） | F52: A2F | G52: Areas to Field | H52: 複数面積の合計をフィールド化 | I52: 18 | J52: 17 | K52: 17 | L52: 17 | M52: =SUM(I52:L52) | N52: 合計面積のフィールド化が秀逸 | O52: Lee Mac | P52: Lee Mac Programming | Q52: 開く | R52: 配布ページからダウンロード | S52: ソース | U52: W51
A53: =RANK(M53,$M$2:$M$6943) | B53: 英語圏 | C53: 画層 | D53: T18,T01 | E53: 画層の自動振り分け・標準化、操作に反応して自動処理（リアクター） | F53: AUTOLAY | G53: AutoLay reactor | H53: 寸法・文字等を自動で指定画層へ | I53: 12 | J53: 18 | K53: 18 | L53: 21 | M53: =SUM(I53:L53) | N53: 標準にもレイヤ自動あり | O53: CAD Studio | P53: CAD Studio | Q53: 開く | R53: 配布ページからダウンロード | S53: ソース/暗号化（.vlx）混在 | U53: W52
A54: =RANK(M54,$M$2:$M$6943) | B54: GitHub | C54: 表・Excel連携 | D54: T16 | E54: 数量拾い・集計表 | F54: haws-tally | G54: CNM Tally | H54: 複数図面の注記数量を集計表へ | I54: 22 | J54: 16 | K54: 21 | L54: 10 | M54: =SUM(I54:L54) | N54: 複数図面の注記数量集計 | O54: Thomas Gail Haws | P54: GitHub: hawstom/cnm | Q54: 開く | R54: GitHub（一括取得可） | S54: ソース | U54: W53
A55: =RANK(M55,$M$2:$M$6943) | B55: 英語圏 | C55: 外部参照・図面管理・一括処理 | D55: T02 | E55: 図面を開かずに一括処理 | F55: DBXSCANBLOCKS | G55: DBXscanBlocks | H55: 図面群から指定ブロックを検索 | I55: 18 | J55: 16 | K55: 18 | L55: 17 | M55: =SUM(I55:L55) | N55: 図面を開かずブロック検索 | O55: CAD Studio | P55: CAD Studio | Q55: 開く | R55: 配布ページからダウンロード | S55: ソース/暗号化（.vlx）混在 | U55: W54
A56: =RANK(M56,$M$2:$M$6943) | B56: GitHub | C56: 引出線・注記 | D56: T11,T21 | E56: 文字の重なりを自動で避ける・整列、動かしながら確認できる編集（動的プレビュー） | F56: MSA7 / MLEADERSMARTALIGN | G56: MLeaderSmartAlign | H56: マルチ引出線をライブプレビューで整列 | I56: 20 | J56: 20 | K56: 14 | L56: 15 | M56: =SUM(I56:L56) | N56: ライブプレビュー整列が秀逸 | O56: ivashinpavel07 | P56: GitHub: ivashinpavel07/AutoCAD-AutoLISP-MLeaderSmartAlign | Q56: 開く | R56: GitHub（一括取得可） | S56: ソース | U56: W55
A57: =RANK(M57,$M$2:$M$6943) | B57: 英語圏 | C57: 外部参照・図面管理・一括処理 | D57: T03 | E57: 複数図面へのスクリプト一括実行 | F57: CDC / ODC | G57: OpenDwgsCmds | H57: 開いた全図面でコマンド実行 | I57: 19 | J57: 15 | K57: 17 | L57: 18 | M57: =SUM(I57:L57) | N57: 開いた全図面でコマンド実行 | O57: Terry Miller | P57: AutoLISP Exchange | Q57: 開く | R57: ファイルを直接ダウンロード | S57: ソース | U57: W56
A58: =RANK(M58,$M$2:$M$6943) | B58: 英語圏 | C58: 寸法 | D58: T07 | E58: 検図：寸法値の手入力上書きを検出 | F58: ODC | G58: OverDimCol (ODC) | H58: 文字上書きされた寸法を強調 | I58: 20 | J58: 17 | K58: 14 | L58: 18 | M58: =SUM(I58:L58) | N58: 上書き寸法検出で品質管理 | O58: CAD Studio | P58: CAD Forum | Q58: 開く | R58: 配布ページからダウンロード | S58: ソース/暗号化（.vlx）混在 | U58: W57
... A62: =RANK(M62,$M$2:$M$6943) | B62: 英語圏 | C62: 印刷・レイアウト・図枠 | D62: T17,T05 | E62: 凡例・画層一覧の自動作成、図枠からレイアウト・ビューポートを自動作成 | F62: - | G62: Viewport Legend | H62: ビューポート内の凡例を自動作成（有料） | I62: 21 | J62: 19 | K62: 15 | L62: 14 | M62: =SUM(I62:L62) | N62: VP内凡例自動は斬新 | O62: Tharwat Al Choufi | P62: Tharwat | Q62: 開く | R62: 有料 | S62: 不明 | U62: W61
A63: =RANK(M63,$M$2:$M$6943) | B63: 中国語圏 | C63: 印刷・レイアウト・図枠 | D63: T04 | E63: 図枠の自動認識→一括印刷 | F63: - | G63: 批量打印（图框为图块/矩形/直线） | H63: 多種図枠を認識して一括印刷 | I63: 18 | J63: 12 | K63: 20 | L63: 19 | M63: =SUM(I63:L63) | N63: 図枠認識印刷 | P63: 晓东CAD家园 | Q63: 開く | R63: フォーラム添付（ログインが必要な場合あり） | S63: 不明 | U63: W62
A64: =RANK(M64,$M$2:$M$6943) | B64: 中国語圏 | C64: 文字・テキスト | D64: T15,T21 | E64: 連番の自動記入、動かしながら確認できる編集（動的プレビュー） | F64: 点哪加哪 | G64: 点哪加哪 (@lisp文本) | H64: 文字内の指定桁をクリックで増分コピー | I64: 18 | J64: 17 | K64: 16 | L64: 18 | M64: =SUM(I64:L64) | N64: 桁指定インクリメントが独創的 | O64: VitalGG | P64: @lisp 应用云 | Q64: 開く | R64: 配布ページからダウンロード | S64: ソース（GitHubにも公開） | U64: W63
A65: =RANK(M65,$M$2:$M$6943) | B65: 中国語圏 | C65: 設定・環境 | D65: T28 | E65: 作業環境の保存・復元 | F65: - | G65: 自动输入法（永久免费） | H65: 編集状況に応じ中英IMEを自動切替 | I65: 22 | J65: 18 | K65: 17 | L65: 12 | M65: =SUM(I65:L65) | N65: IME自動切替 | O65: moy838840554 | P65: 明经CAD社区 | Q65: 開く | R65: フォーラム添付（ログインが必要な場合あり） | S65: 不明 | U65: W64
A66: =RANK(M66,$M$2:$M$6943) | B66: 中国語圏 | C66: 選択・絞り込み | D66: その他 | E66: その他 | F66: ss1~ss5 | G66: 选择集记忆 (@lisp选择) | H66: 選択セットを5つまで記憶・再呼出 | I66: 18 | J66: 15 | K66: 16 | L66: 20 | M66: =SUM(I66:L66) | N66: 名前付き選択セット | O66: VitalGG | P66: @lisp 应用云 | Q66: 開く | R66: 配布ページからダウンロード | S66: ソース（GitHubにも公開） | U66: W65
A67: =RANK(M67,$M$2:$M$6943) | B67: 中国語圏 | C67: 線・ポリライン編集 | D67: T21 | E67: 動かしながら確認できる編集（動的プレビュー） | F67: - | G67: 阿甘超级复制V5.0 | H67: 多機能な動的複写 | I67: 17 | J67: 17 | K67: 16 | L67: 19 | M67: =SUM(I67:L67) | N67: 動的複写 | O67: dtucad | P67: 明经CAD社区 | Q67: 開く | R67: フォーラム添付（ログインが必要な場合あり） | S67: 不明 | U67: W66
A68: =RANK(M68,$M$2:$M$6943) | B68: ヨーロッパ | C68: 外部参照・図面管理・一括処理 | D68: T02,T03 | E68: 図面を開かずに一括処理、複数図面へのスクリプト一括実行 | F68: - | G68: ACCORE | H68: accoreconsoleで数百図面にスクリプト/LISPを一括適用 | I68: 19 | J68: 15 | K68: 19 | L68: 15 | M68: =SUM(I68:L68) | N68: コアコンソールで高速一括 | O68: Fraiddd | P68: GitHub: Fraiddd/ACCORE | Q68: 開く | R68: GitHub（一括取得可） | S68: ソース | U68: W67
A69: =RANK(M69,$M$2:$M$6943) | B69: その他の地域 | C69: 印刷・レイアウト・図枠 | D69: T05 | E69: 図枠からレイアウト・ビューポートを自動作成 | F69: AUTOLAMINAS | G69: AUTOLAMINAS | H69: モデルの図枠を走査し各レイアウトにVP自動作成 | I69: 22 | J69: 16 | K69: 18 | L69: 12 | M69: =SUM(I69:L69) | N69: 図枠走査でVP自動作成 | O69: Erick Holger Perez Mescco | P69: GitHub: erickholger2025-sudo/AUTOLISP_AUTOCAD | Q69: 開く | R69: GitHub（一括取得可） | S69: ソース | U69: W68
A70: =RANK(M70,$M$2:$M$6943) | B70: ヨーロッパ | C70: 外部参照・図面管理・一括処理 | D70: T02,T16 | E70: 図面を開かずに一括処理、数量拾い・集計表 | F70: - | G70: odbx_get* | H70: 未オープンの多数図面から画層一覧・ブロック数・ポリ長さ等を抽出 | I70: 20 | J70: 15 | K70: 18 | L70: 15 | M70: =SUM(I70:L70) | N70: 図面を開かず情報抽出 | O70: Fraiddd | P70: GitHub: Fraiddd/ODBX_LIB | Q70: 開く | R70: GitHub（一括取得可） | S70: ソース | U70: W69
A71: =RANK(M71,$M$2:$M$6943) | B71: ヨーロッパ | C71: ハッチ・面積・長さ集計 | D71: T13 | E71: 図形と数値の連動（フィールド・面積表） | F71: totalarea / areaupd / areaedit | G71: TotalArea | H71: リンクした図形群の合計面積を属性に動的表示 | I71: 19 | J71: 20 | K71: 16 | L71: 13 | M71: =SUM(I71:L71) | N71: 面積をリアクタで自動更新 | O71: (gile) | P71: gileCAD | Q71: 開く | R71: 配布ページからダウンロード | S71: ソース | U71: W70
A72: =RANK(M72,$M$2:$M$6943) | B72: 中国語圏 | C72: 文字・テキスト | D72: T12 | E72: 文字の一括検索・置換 | F72: QE | G72: ZW工具 QE 剪贴板批量替换文字 | H72: クリップボードの行で選択文字を順に置換 | I72: 20 | J72: 17 | K72: 16 | L72: 15 | M72: =SUM(I72:L72) | N72: Excel列を図面へ流込 | O72: y1991427360s | P72: GitHub: y1991427360s/zwcad-autolisp-tools | Q72: 開く | R72: GitHub（一括取得可） | S72: ソース | U72: W71
A73: =RANK(M73,$M$2:$M$6943) | B73: ベトナム・東南アジア | C73: 画層 | D73: T01,T18 | E73: 操作に反応して自動処理（リアクター）、画層の自動振り分け・標準化 | F73: - | G73: Ứng dụng REACTOR trong quản lý bản vẽ theo layer | H73: リアクタで作図画層を自動管理 | I73: 19 | J73: 20 | K73: 13 | L73: 16 | M73: =SUM(I73:L73) | N73: 画層をリアクタで自動管理 | O73: CADViet member | P73: CADViet | Q73: 開く | R73: フォーラム添付（ログインが必要な場合あり） | S73: 不明 | U73: W72
A74: =RANK(M74,$M$2:$M$6943) | B74: 中国語圏 | C74: 印刷・レイアウト・図枠 | D74: T04 | E74: 図枠の自動認識→一括印刷 | F74: - | G74: 依云CAD批量打图精灵9.0 | H74: 一括印刷ソフト | I74: 18 | J74: 10 | K74: 20 | L74: 20 | M74: =SUM(I74:L74) | N74: 一括印刷 | O74: 渴望光明88 | P74: 明经CAD社区 | Q74: 開く | R74: フォーラム添付（ログインが必要な場合あり） | S74: 不明 | U74: W73
...

Sheet テーマ別集計
A1: テーマ | B1: テーマ名 | C1: 関連件数 | D1: うち70点以上 | E1: GitHub（一括取得可） | F1: ファイルを直接ダウンロード | G1: 配布ページからダウンロード | H1: ページ内にコード掲載 | I1: フォーラム添付（ログインが必要な場合あり） | J1: ログイン・会員登録が必要 | K1: 有料 | L1: アプリストア経由（Autodeskアカウントが必要） | M1: アクセス制限あり | N1: サイト閉鎖・リンク切れ
A2: その他 | B2: その他 | C2: =COUNTIF(総合一覧!$D$2:$D$6943,"*"&A2&"*") | D2: =COUNTIFS(総合一覧!$D$2:$D$6943,"*"&A2&"*",総合一覧!$M$2:$M$6943,">=70") | E2: =COUNTIFS(総合一覧!$D$2:$D$6943,"*"&$A2&"*",総合一覧!$R$2:$R$6943,E$1) | F2: =COUNTIFS(総合一覧!$D$2:$D$6943,"*"&$A2&"*",総合一覧!$R$2:$R$6943,F$1) | G2: =COUNTIFS(総合一覧!$D$2:$D$6943,"*"&$A2&"*",総合一覧!$R$2:$R$6943,G$1) | H2: =COUNTIFS(総合一覧!$D$2:$D$6943,"*"&$A2&"*",総合一覧!$R$2:$R$6943,H$1) | I2: =COUNTIFS(総合一覧!$D$2:$D$6943,"*"&$A2&"*",総合一覧!$R$2:$R$6943,I$1) | J2: =COUNTIFS(総合一覧!$D$2:$D$6943,"*"&$A2&"*",総合一覧!$R$2:$R$6943,J$1) | K2: =COUNTIFS(総合一覧!$D$2:$D$6943,"*"&$A2&"*",総合一覧!$R$2:$R$6943,K$1) | L2: =COUNTIFS(総合一覧!$D$2:$D$6943,"*"&$A2&"*",総合一覧!$R$2:$R$6943,L$1) | ... N2: =COUNTIFS(総合一覧!$D$2:$D$6943,"*"&$A2&"*",総合一覧!$R$2:$R$6943,N$1)
A3: T01 | B3: 操作に反応して自動処理（リアクター） | C3: =COUNTIF(総合一覧!$D$2:$D$6943,"*"&A3&"*") | D3: =COUNTIFS(総合一覧!$D$2:$D$6943,"*"&A3&"*",総合一覧!$M$2:$M$6943,">=70") | E3: =COUNTIFS(総合一覧!$D$2:$D$6943,"*"&$A3&"*",総合一覧!$R$2:$R$6943,E$1) | F3: =COUNTIFS(総合一覧!$D$2:$D$6943,"*"&$A3&"*",総合一覧!$R$2:$R$6943,F$1) | G3: =COUNTIFS(総合一覧!$D$2:$D$6943,"*"&$A3&"*",総合一覧!$R$2:$R$6943,G$1) | H3: =COUNTIFS(総合一覧!$D$2:$D$6943,"*"&$A3&"*",総合一覧!$R$2:$R$6943,H$1) | I3: =COUNTIFS(総合一覧!$D$2:$D$6943,"*"&$A3&"*",総合一覧!$R$2:$R$6943,I$1) | J3: =COUNTIFS(総合一覧!$D$2:$D$6943,"*"&$A3&"*",総合一覧!$R$2:$R$6943,J$1) | K3: =COUNTIFS(総合一覧!$D$2:$D$6943,"*"&$A3&"*",総合一覧!$R$2:$R$6943,K$1) | L3: =COUNTIFS(総合一覧!$D$2:$D$6943,"*"&$A3&"*",総合一覧!$R$2:$R$6943,L$1) | ... N3: =COUNTIFS(総合一覧!$D$2:$D$6943,"*"&$A3&"*",総合一覧!$R$2:$R$6943,N$1)
A4: T02 | B4: 図面を開かずに一括処理 | C4: =COUNTIF(総合一覧!$D$2:$D$6943,"*"&A4&"*") | D4: =COUNTIFS(総合一覧!$D$2:$D$6943,"*"&A4&"*",総合一覧!$M$2:$M$6943,">=70") | E4: =COUNTIFS(総合一覧!$D$2:$D$6943,"*"&$A4&"*",総合一覧!$R$2:$R$6943,E$1) | F4: =COUNTIFS(総合一覧!$D$2:$D$6943,"*"&$A4&"*",総合一覧!$R$2:$R$6943,F$1) | G4: =COUNTIFS(総合一覧!$D$2:$D$6943,"*"&$A4&"*",総合一覧!$R$2:$R$6943,G$1) | H4: =COUNTIFS(総合一覧!$D$2:$D$6943,"*"&$A4&"*",総合一覧!$R$2:$R$6943,H$1) | I4: =COUNTIFS(総合一覧!$D$2:$D$6943,"*"&$A4&"*",総合一覧!$R$2:$R$6943,I$1) | J4: =COUNTIFS(総合一覧!$D$2:$D$6943,"*"&$A4&"*",総合一覧!$R$2:$R$6943,J$1) | K4: =COUNTIFS(総合一覧!$D$2:$D$6943,"*"&$A4&"*",総合一覧!$R$2:$R$6943,K$1) | L4: =COUNTIFS(総合一覧!$D$2:$D$6943,"*"&$A4&"*",総合一覧!$R$2:$R$6943,L$1) | ... N4: =COUNTIFS(総合一覧!$D$2:$D$6943,"*"&$A4&"*",総合一覧!$R$2:$R$6943,N$1)
A5: T03 | B5: 複数図面へのスクリプト一括実行 | C5: =COUNTIF(総合一覧!$D$2:$D$6943,"*"&A5&"*") | D5: =COUNTIFS(総合一覧!$D$2:$D$6943,"*"&A5&"*",総合一覧!$M$2:$M$6943,">=70") | E5: =COUNTIFS(総合一覧!$D$2:$D$6943,"*"&$A5&"*",総合一覧!$R$2:$R$6943,E$1) | F5: =COUNTIFS(総合一覧!$D$2:$D$6943,"*"&$A5&"*",総合一覧!$R$2:$R$6943,F$1) | G5: =COUNTIFS(総合一覧!$D$2:$D$6943,"*"&$A5&"*",総合一覧!$R$2:$R$6943,G$1) | H5: =COUNTIFS(総合一覧!$D$2:$D$6943,"*"&$A5&"*",総合一覧!$R$2:$R$6943,H$1) | I5: =COUNTIFS(総合一覧!$D$2:$D$6943,"*"&$A5&"*",総合一覧!$R$2:$R$6943,I$1) | J5: =COUNTIFS(総合一覧!$D$2:$D$6943,"*"&$A5&"*",総合一覧!$R$2:$R$6943,J$1) | K5: =COUNTIFS(総合一覧!$D$2:$D$6943,"*"&$A5&"*",総合一覧!$R$2:$R$6943,K$1) | L5: =COUNTIFS(総合一覧!$D$2:$D$6943,"*"&$A5&"*",総合一覧!$R$2:$R$6943,L$1) | ... N5: =COUNTIFS(総合一覧!$D$2:$D$6943,"*"&$A5&"*",総合一覧!$R$2:$R$6943,N$1)
A6: T04 | B6: 図枠の自動認識→一括印刷 | C6: =COUNTIF(総合一覧!$D$2:$D$6943,"*"&A6&"*") | D6: =COUNTIFS(総合一覧!$D$2:$D$6943,"*"&A6&"*",総合一覧!$M$2:$M$6943,">=70") | E6: =COUNTIFS(総合一覧!$D$2:$D$6943,"*"&$A6&"*",総合一覧!$R$2:$R$6943,E$1) | F6: =COUNTIFS(総合一覧!$D$2:$D$6943,"*"&$A6&"*",総合一覧!$R$2:$R$6943,F$1) | G6: =COUNTIFS(総合一覧!$D$2:$D$6943,"*"&$A6&"*",総合一覧!$R$2:$R$6943,G$1) | H6: =COUNTIFS(総合一覧!$D$2:$D$6943,"*"&$A6&"*",総合一覧!$R$2:$R$6943,H$1) | I6: =COUNTIFS(総合一覧!$D$2:$D$6943,"*"&$A6&"*",総合一覧!$R$2:$R$6943,I$1) | J6: =COUNTIFS(総合一覧!$D$2:$D$6943,"*"&$A6&"*",総合一覧!$R$2:$R$6943,J$1) | K6: =COUNTIFS(総合一覧!$D$2:$D$6943,"*"&$A6&"*",総合一覧!$R$2:$R$6943,K$1) | L6: =COUNTIFS(総合一覧!$D$2:$D$6943,"*"&$A6&"*",総合一覧!$R$2:$R$6943,L$1) | ... N6: =COUNTIFS(総合一覧!$D$2:$D$6943,"*"&$A6&"*",総合一覧!$R$2:$R$6943,N$1)
A7: T05 | B7: 図枠からレイアウト・ビューポートを自動作成 | C7: =COUNTIF(総合一覧!$D$2:$D$6943,"*"&A7&"*") | D7: =COUNTIFS(総合一覧!$D$2:$D$6943,"*"&A7&"*",総合一覧!$M$2:$M$6943,">=70") | E7: =COUNTIFS(総合一覧!$D$2:$D$6943,"*"&$A7&"*",総合一覧!$R$2:$R$6943,E$1) | F7: =COUNTIFS(総合一覧!$D$2:$D$6943,"*"&$A7&"*",総合一覧!$R$2:$R$6943,F$1) | G7: =COUNTIFS(総合一覧!$D$2:$D$6943,"*"&$A7&"*",総合一覧!$R$2:$R$6943,G$1) | H7: =COUNTIFS(総合一覧!$D$2:$D$6943,"*"&$A7&"*",総合一覧!$R$2:$R$6943,H$1) | I7: =COUNTIFS(総合一覧!$D$2:$D$6943,"*"&$A7&"*",総合一覧!$R$2:$R$6943,I$1) | J7: =COUNTIFS(総合一覧!$D$2:$D$6943,"*"&$A7&"*",総合一覧!$R$2:$R$6943,J$1) | K7: =COUNTIFS(総合一覧!$D$2:$D$6943,"*"&$A7&"*",総合一覧!$R$2:$R$6943,K$1) | L7: =COUNTIFS(総合一覧!$D$2:$D$6943,"*"&$A7&"*",総合一覧!$R$2:$R$6943,L$1) | ... N7: =COUNTIFS(総合一覧!$D$2:$D$6943,"*"&$A7&"*",総合一覧!$R$2:$R$6943,N$1)
A8: T06 | B8: 図枠の属性を自動更新 | C8: =COUNTIF(総合一覧!$D$2:$D$6943,"*"&A8&"*") | D8: =COUNTIFS(総合一覧!$D$2:$D$6943,"*"&A8&"*",総合一覧!$M$2:$M$6943,">=70") | E8: =COUNTIFS(総合一覧!$D$2:$D$6943,"*"&$A8&"*",総合一覧!$R$2:$R$6943,E$1) | F8: =COUNTIFS(総合一覧!$D$2:$D$6943,"*"&$A8&"*",総合一覧!$R$2:$R$6943,F$1) | G8: =COUNTIFS(総合一覧!$D$2:$D$6943,"*"&$A8&"*",総合一覧!$R$2:$R$6943,G$1) | H8: =COUNTIFS(総合一覧!$D$2:$D$6943,"*"&$A8&"*",総合一覧!$R$2:$R$6943,H$1) | I8: =COUNTIFS(総合一覧!$D$2:$D$6943,"*"&$A8&"*",総合一覧!$R$2:$R$6943,I$1) | J8: =COUNTIFS(総合一覧!$D$2:$D$6943,"*"&$A8&"*",総合一覧!$R$2:$R$6943,J$1) | K8: =COUNTIFS(総合一覧!$D$2:$D$6943,"*"&$A8&"*",総合一覧!$R$2:$R$6943,K$1) | L8: =COUNTIFS(総合一覧!$D$2:$D$6943,"*"&$A8&"*",総合一覧!$R$2:$R$6943,L$1) | ... N8: =COUNTIFS(総合一覧!$D$2:$D$6943,"*"&$A8&"*",総合一覧!$R$2:$R$6943,N$1)
A9: T07 | B9: 検図：寸法値の手入力上書きを検出 | C9: =COUNTIF(総合一覧!$D$2:$D$6943,"*"&A9&"*") | D9: =COUNTIFS(総合一覧!$D$2:$D$6943,"*"&A9&"*",総合一覧!$M$2:$M$6943,">=70") | E9: =COUNTIFS(総合一覧!$D$2:$D$6943,"*"&$A9&"*",総合一覧!$R$2:$R$6943,E$1) | F9: =COUNTIFS(総合一覧!$D$2:$D$6943,"*"&$A9&"*",総合一覧!$R$2:$R$6943,F$1) | G9: =COUNTIFS(総合一覧!$D$2:$D$6943,"*"&$A9&"*",総合一覧!$R$2:$R$6943,G$1) | H9: =COUNTIFS(総合一覧!$D$2:$D$6943,"*"&$A9&"*",総合一覧!$R$2:$R$6943,H$1) | I9: =COUNTIFS(総合一覧!$D$2:$D$6943,"*"&$A9&"*",総合一覧!$R$2:$R$6943,I$1) | J9: =COUNTIFS(総合一覧!$D$2:$D$6943,"*"&$A9&"*",総合一覧!$R$2:$R$6943,J$1) | K9: =COUNTIFS(総合一覧!$D$2:$D$6943,"*"&$A9&"*",総合一覧!$R$2:$R$6943,K$1) | L9: =COUNTIFS(総合一覧!$D$2:$D$6943,"*"&$A9&"*",総合一覧!$R$2:$R$6943,L$1) | ... N9: =COUNTIFS(総合一覧!$D$2:$D$6943,"*"&$A9&"*",総合一覧!$R$2:$R$6943,N$1)
A10: T08 | B10: 検図：わずかなずれ・隙間・重なりを検出 | C10: =COUNTIF(総合一覧!$D$2:$D$6943,"*"&A10&"*") | D10: =COUNTIFS(総合一覧!$D$2:$D$6943,"*"&A10&"*",総合一覧!$M$2:$M$6943,">=70") | E10: =COUNTIFS(総合一覧!$D$2:$D$6943,"*"&$A10&"*",総合一覧!$R$2:$R$6943,E$1) | F10: =COUNTIFS(総合一覧!$D$2:$D$6943,"*"&$A10&"*",総合一覧!$R$2:$R$6943,F$1) | G10: =COUNTIFS(総合一覧!$D$2:$D$6943,"*"&$A10&"*",総合一覧!$R$2:$R$6943,G$1) | H10: =COUNTIFS(総合一覧!$D$2:$D$6943,"*"&$A10&"*",総合一覧!$R$2:$R$6943,H$1) | I10: =COUNTIFS(総合一覧!$D$2:$D$6943,"*"&$A10&"*",総合一覧!$R$2:$R$6943,I$1) | J10: =COUNTIFS(総合一覧!$D$2:$D$6943,"*"&$A10&"*",総合一覧!$R$2:$R$6943,J$1) | K10: =COUNTIFS(総合一覧!$D$2:$D$6943,"*"&$A10&"*",総合一覧!$R$2:$R$6943,K$1) | L10: =COUNTIFS(総合一覧!$D$2:$D$6943,"*"&$A10&"*",総合一覧!$R$2:$R$6943,L$1) | ... N10: =COUNTIFS(総合一覧!$D$2:$D$6943,"*"&$A10&"*",総合一覧!$R$2:$R$6943,N$1)
A11: T09 | B11: 新旧図面の差分比較・雲マーク | C11: =COUNTIF(総合一覧!$D$2:$D$6943,"*"&A11&"*") | D11: =COUNTIFS(総合一覧!$D$2:$D$6943,"*"&A11&"*",総合一覧!$M$2:$M$6943,">=70") | E11: =COUNTIFS(総合一覧!$D$2:$D$6943,"*"&$A11&"*",総合一覧!$R$2:$R$6943,E$1) | F11: =COUNTIFS(総合一覧!$D$2:$D$6943,"*"&$A11&"*",総合一覧!$R$2:$R$6943,F$1) | G11: =COUNTIFS(総合一覧!$D$2:$D$6943,"*"&$A11&"*",総合一覧!$R$2:$R$6943,G$1) | H11: =COUNTIFS(総合一覧!$D$2:$D$6943,"*"&$A11&"*",総合一覧!$R$2:$R$6943,H$1) | I11: =COUNTIFS(総合一覧!$D$2:$D$6943,"*"&$A11&"*",総合一覧!$R$2:$R$6943,I$1) | J11: =COUNTIFS(総合一覧!$D$2:$D$6943,"*"&$A11&"*",総合一覧!$R$2:$R$6943,J$1) | K11: =COUNTIFS(総合一覧!$D$2:$D$6943,"*"&$A11&"*",総合一覧!$R$2:$R$6943,K$1) | L11: =COUNTIFS(総合一覧!$D$2:$D$6943,"*"&$A11&"*",総合一覧!$R$2:$R$6943,L$1) | ... N11: =COUNTIFS(総合一覧!$D$2:$D$6943,"*"&$A11&"*",総合一覧!$R$2:$R$6943,N$1)
A12: T10 | B12: 図面の健全性チェック・お掃除 | C12: =COUNTIF(総合一覧!$D$2:$D$6943,"*"&A12&"*") | D12: =COUNTIFS(総合一覧!$D$2:$D$6943,"*"&A12&"*",総合一覧!$M$2:$M$6943,">=70") | E12: =COUNTIFS(総合一覧!$D$2:$D$6943,"*"&$A12&"*",総合一覧!$R$2:$R$6943,E$1) | F12: =COUNTIFS(総合一覧!$D$2:$D$6943,"*"&$A12&"*",総合一覧!$R$2:$R$6943,F$1) | G12: =COUNTIFS(総合一覧!$D$2:$D$6943,"*"&$A12&"*",総合一覧!$R$2:$R$6943,G$1) | H12: =COUNTIFS(総合一覧!$D$2:$D$6943,"*"&$A12&"*",総合一覧!$R$2:$R$6943,H$1) | I12: =COUNTIFS(総合一覧!$D$2:$D$6943,"*"&$A12&"*",総合一覧!$R$2:$R$6943,I$1) | J12: =COUNTIFS(総合一覧!$D$2:$D$6943,"*"&$A12&"*",総合一覧!$R$2:$R$6943,J$1) | K12: =COUNTIFS(総合一覧!$D$2:$D$6943,"*"&$A12&"*",総合一覧!$R$2:$R$6943,K$1) | L12: =COUNTIFS(総合一覧!$D$2:$D$6943,"*"&$A12&"*",総合一覧!$R$2:$R$6943,L$1) | ... N12: =COUNTIFS(総合一覧!$D$2:$D$6943,"*"&$A12&"*",総合一覧!$R$2:$R$6943,N$1)
A13: T11 | B13: 文字の重なりを自動で避ける・整列 | C13: =COUNTIF(総合一覧!$D$2:$D$6943,"*"&A13&"*") | D13: =COUNTIFS(総合一覧!$D$2:$D$6943,"*"&A13&"*",総合一覧!$M$2:$M$6943,">=70") | E13: =COUNTIFS(総合一覧!$D$2:$D$6943,"*"&$A13&"*",総合一覧!$R$2:$R$6943,E$1) | F13: =COUNTIFS(総合一覧!$D$2:$D$6943,"*"&$A13&"*",総合一覧!$R$2:$R$6943,F$1) | G13: =COUNTIFS(総合一覧!$D$2:$D$6943,"*"&$A13&"*",総合一覧!$R$2:$R$6943,G$1) | H13: =COUNTIFS(総合一覧!$D$2:$D$6943,"*"&$A13&"*",総合一覧!$R$2:$R$6943,H$1) | I13: =COUNTIFS(総合一覧!$D$2:$D$6943,"*"&$A13&"*",総合一覧!$R$2:$R$6943,I$1) | J13: =COUNTIFS(総合一覧!$D$2:$D$6943,"*"&$A13&"*",総合一覧!$R$2:$R$6943,J$1) | K13: =COUNTIFS(総合一覧!$D$2:$D$6943,"*"&$A13&"*",総合一覧!$R$2:$R$6943,K$1) | L13: =COUNTIFS(総合一覧!$D$2:$D$6943,"*"&$A13&"*",総合一覧!$R$2:$R$6943,L$1) | ... N13: =COUNTIFS(総合一覧!$D$2:$D$6943,"*"&$A13&"*",総合一覧!$R$2:$R$6943,N$1)
... A32: T30 | B32: AI・OCR・翻訳など新技術との連携 | C32: =COUNTIF(総合一覧!$D$2:$D$6943,"*"&A32&"*") | D32: =COUNTIFS(総合一覧!$D$2:$D$6943,"*"&A32&"*",総合一覧!$M$2:$M$6943,">=70") | E32: =COUNTIFS(総合一覧!$D$2:$D$6943,"*"&$A32&"*",総合一覧!$R$2:$R$6943,E$1) | F32: =COUNTIFS(総合一覧!$D$2:$D$6943,"*"&$A32&"*",総合一覧!$R$2:$R$6943,F$1) | G32: =COUNTIFS(総合一覧!$D$2:$D$6943,"*"&$A32&"*",総合一覧!$R$2:$R$6943,G$1) | H32: =COUNTIFS(総合一覧!$D$2:$D$6943,"*"&$A32&"*",総合一覧!$R$2:$R$6943,H$1) | I32: =COUNTIFS(総合一覧!$D$2:$D$6943,"*"&$A32&"*",総合一覧!$R$2:$R$6943,I$1) | J32: =COUNTIFS(総合一覧!$D$2:$D$6943,"*"&$A32&"*",総合一覧!$R$2:$R$6943,J$1) | K32: =COUNTIFS(総合一覧!$D$2:$D$6943,"*"&$A32&"*",総合一覧!$R$2:$R$6943,K$1) | L32: =COUNTIFS(総合一覧!$D$2:$D$6943,"*"&$A32&"*",総合一覧!$R$2:$R$6943,L$1) | ... N32: =COUNTIFS(総合一覧!$D$2:$D$6943,"*"&$A32&"*",総合一覧!$R$2:$R$6943,N$1)
A34: ※「入手方法」「形式」はURLや取得元サイトの傾向から判断した見込みです。実際のダウンロード時に確認します。

Sheet 分野別TOP10
A1: 分野別 上位10件（作成時点の点数で抽出。点数を変えても自動では並び替わりません）
A3: 01
A4: 順 | B4: 名前 | C4: 何をするツールか | D4: 合計 | E4: 地域 | F4: サイト | G4: リンク
A5: 1 | B5: Довольно мощный автонумератор и не только. | C5: 強力な自動連番・値変更 | D5: 54 | E5: ロシア語圏 | F5: dwg.ru | G5: 開く
A6: 2 | B6: INCDEC v 02.17 | C6: 注記の連番・加減算・値交換 | D6: 53 | E6: ロシア語圏 | F6: dwg.ru | G6: 開く
A7: 3 | B7: AsmiTools: TTC.LSP | C7: 文字・表・寸法・属性間で内容コピー | D7: 52 | E7: ロシア語圏 | F7: dwg.ru | G7: 開く
A8: 4 | B8: Довольно мощный копировщик текста и не только | C8: 文字・属性値の強力コピー | D8: 52 | E8: ロシア語圏 | F8: dwg.ru | G8: 開く
A9: 5 | B9: AsmiTools: NUM.LSP | C9: 接頭辞・接尾辞付き動的連番 | D9: 51 | E9: ロシア語圏 | F9: dwg.ru | G9: 開く
A10: 6 | B10: Многозадачный поиск и замена текста по маске | C10: マスク指定で多重検索置換 | D10: 51 | E10: ロシア語圏 | F10: dwg.ru | G10: 開く
A11: 7 | B11: Нумеровщик с префиксом, изменяемой частью и суффиксом | C11: 接頭辞・接尾辞付き連番記入 | D11: 51 | E11: ロシア語圏 | F11: dwg.ru | G11: 開く
A12: 8 | B12: Программа с функциями для действий с текстовыми примитивами. v.1.3 | C12: 文字の連番・四則演算 | D12: 51 | E12: ロシア語圏 | F12: dwg.ru | G12: 開く
A13: 9 | B13: LISP для замены высоты текста на чертеже | C13: 全文字高さを0.5刻みに丸め | D13: 50 | E13: ロシア語圏 | F13: dwg.ru | G13: 開く
A14: 10 | B14: ClearTextsByRadius.LISP | C14: 半径内の重なる文字を間引く | D14: 49 | E14: ロシア語圏 | F14: geodesist.ru | G14: 開く
A16: 文字・テキスト
A17: 順 | B17: 名前 | C17: 何をするツールか | D17: 合計 | E17: 地域 | F17: サイト | G17: リンク
A18: 1 | B18: 文字避让 (@lisp文本) | C18: 重なった単線文字を自動で逃がし配置 | D18: 77 | E18: 中国語圏 | F18: @lisp 应用云 | G18: 開く
A19: 2 | B19: Incremental Numbering Suite | C19: 連番文字・属性を配置 | D19: 76 | E19: 英語圏 | F19: Lee Mac Programming | G19: 開く
A20: 3 | B20: ZW工具 AW 文字自动避让 | C20: 文字を微移動して線・他文字との重なりを回避 | D20: 74 | E20: 中国語圏 | F20: GitHub: y1991427360s/zwcad-autolisp-tools | G20: 開く
A21: 4 | B21: RegExpCnt | C21: 正規表現で文字を置換・連番 | D21: 72 | E21: 英語圏 | F21: CAD Studio | G21: 開く
A22: 5 | B22: TxtOverlap | C22: 重なった文字を検出 | D22: 72 | E22: 英語圏 | F22: CAD Forum | G22: 開く
A23: 6 | B23: Incremental Array | C23: 連番を増やしながら配列複写 | D23: 71 | E23: 英語圏 | F23: Lee Mac Programming | G23: 開く
A24: 7 | B24: Incremental Numbering (NumInc) | C24: 連番テキスト・ブロックを配置 | D24: 70 | E24: 英語圏 | F24: MEP WORK | G24: 開く
A25: 8 | B25: Lisp dịch thuật bản vẽ song ngữ AutoCAD | C25: AIで図面文字を対訳翻訳（有料） | D25: 70 | E25: ベトナム・東南アジア | F25: lisp.vn (AutoLISP Reviewer) | G25: 開く
A26: 9 | B26: 定位压线字 (@lisp文本) | C26: 線と重なっている文字を強調表示 | D26: 70 | E26: 中国語圏 | F26: @lisp 应用云 | G26: 開く
A27: 10 | B27: PDFOCRTEXT PDF转CAD文字OCR | C27: PDF由来の線文字をOCRしてMTEXT化 | D27: 69 | E27: 中国語圏 | F27: GitHub: y1991427360s/pdf2cad-ocr-text-helper | G27: 開く
A29: 02
A30: 順 | B30: 名前 | C30: 何をするツールか | D30: 合計 | E30: 地域 | F30: サイト | G30: リンク
A31: 1 | B31: Визуальный контроль масштабного к-та (DIMLFAC) размеров! | C31: 寸法の尺度係数を色で可視化 | D31: 59 | E31: ロシア語圏 | F31: dwg.ru | G31: 開く
A32: 2 | B32: Программа AutoDim, автоматом строит цепочки размеров, образмеривает окружности и т.д. | C32: 直列寸法や円寸法を自動記入 | D32: 55 | E32: ロシア語圏 | F32: dwg.ru | G32: 開く
A33: 3 | B33: FreeHandDim | C33: 手入力寸法値を検出し赤色化 | D33: 51 | E33: ロシア語圏 | F33: cad.dp.ua | G33: 開く
A34: 4 | B34: AsmiTools: PDIM.LSP | C34: 複数ポリラインに一括寸法 | D34: 48 | E34: ロシア語圏 | F34: dwg.ru | G34: 開く
A35: 5 | B35: Простановка длин полилиний и отрезков в средней точке | C35: 線の中点に長さを記入 | D35: 47 | E35: ロシア語圏 | F35: forum.dwg.ru | G35: 開く
A36: 6 | B36: DimReduct исправление перевернутых размеров | C36: 反転した寸法を正しい向きに修正 | D36: 45 | E36: ロシア語圏 | F36: dwg.ru | G36: 開く
A37: 7 | B37: Нанесение размеров на аксонометрических проекциях | C37: アイソメ図に寸法記入 | D37: 44 | E37: ロシア語圏 | F37: dwg.ru | G37: 開く
A38: 8 | B38: DSK v0.7L - программа для простановки размеров | C38: 公差付き寸法を記入 | D38: 41 | E38: ロシア語圏 | F38: dwg.ru | G38: 開く
A39: 9 | B39: DIMRR | C39: 許容範囲内で実測寸法値を作成 | D39: 40 | E39: ロシア語圏 | F39: ispolnitelnaya-shema.ru | G39: 開く
A40: 10 | B40: Лисп DIMR | C40: 寸法の分母に実測値を記入 | D40: 38 | E40: ロシア語圏 | F40: geodesist.ru | G40: 開く
A42: 寸法
A43: 順 | B43: 名前 | C43: 何をするツールか | D43: 合計 | E43: 地域 | F43: サイト | G43: リンク
A44: 1 | B44: DIMPOLICE | C44: 書き換えられた寸法値を検出（有料） | D44: 73 | E44: 日本 | F44: note (chiko_root) | G44: 開く
...

Sheet 地域別集計
A1: 地域 | B1: 件数 | C1: 平均点 | D1: 最高点 | E1: 70点以上の件数
A2: 英語圏 | B2: =COUNTIF(総合一覧!$B$2:$B$6943,A2) | C2: =ROUND(AVERAGEIF(総合一覧!$B$2:$B$6943,A2,総合一覧!$M$2:$M$6943),1) | D2: =_xlfn.MAXIFS(総合一覧!$M$2:$M$6943,総合一覧!$B$2:$B$6943,A2) | E2: =COUNTIFS(総合一覧!$B$2:$B$6943,A2,総合一覧!$M$2:$M$6943,">=70")
A3: 日本 | B3: =COUNTIF(総合一覧!$B$2:$B$6943,A3) | C3: =ROUND(AVERAGEIF(総合一覧!$B$2:$B$6943,A3,総合一覧!$M$2:$M$6943),1) | D3: =_xlfn.MAXIFS(総合一覧!$M$2:$M$6943,総合一覧!$B$2:$B$6943,A3) | E3: =COUNTIFS(総合一覧!$B$2:$B$6943,A3,総合一覧!$M$2:$M$6943,">=70")
A4: 中国語圏 | B4: =COUNTIF(総合一覧!$B$2:$B$6943,A4) | C4: =ROUND(AVERAGEIF(総合一覧!$B$2:$B$6943,A4,総合一覧!$M$2:$M$6943),1) | D4: =_xlfn.MAXIFS(総合一覧!$M$2:$M$6943,総合一覧!$B$2:$B$6943,A4) | E4: =COUNTIFS(総合一覧!$B$2:$B$6943,A4,総合一覧!$M$2:$M$6943,">=70")
A5: ロシア語圏 | B5: =COUNTIF(総合一覧!$B$2:$B$6943,A5) | C5: =ROUND(AVERAGEIF(総合一覧!$B$2:$B$6943,A5,総合一覧!$M$2:$M$6943),1) | D5: =_xlfn.MAXIFS(総合一覧!$M$2:$M$6943,総合一覧!$B$2:$B$6943,A5) | E5: =COUNTIFS(総合一覧!$B$2:$B$6943,A5,総合一覧!$M$2:$M$6943,">=70")
A6: ベトナム・東南アジア | B6: =COUNTIF(総合一覧!$B$2:$B$6943,A6) | C6: =ROUND(AVERAGEIF(総合一覧!$B$2:$B$6943,A6,総合一覧!$M$2:$M$6943),1) | D6: =_xlfn.MAXIFS(総合一覧!$M$2:$M$6943,総合一覧!$B$2:$B$6943,A6) | E6: =COUNTIFS(総合一覧!$B$2:$B$6943,A6,総合一覧!$M$2:$M$6943,">=70")
A7: ヨーロッパ | B7: =COUNTIF(総合一覧!$B$2:$B$6943,A7) | C7: =ROUND(AVERAGEIF(総合一覧!$B$2:$B$6943,A7,総合一覧!$M$2:$M$6943),1) | D7: =_xlfn.MAXIFS(総合一覧!$M$2:$M$6943,総合一覧!$B$2:$B$6943,A7) | E7: =COUNTIFS(総合一覧!$B$2:$B$6943,A7,総合一覧!$M$2:$M$6943,">=70")
A8: その他の地域 | B8: =COUNTIF(総合一覧!$B$2:$B$6943,A8) | C8: =ROUND(AVERAGEIF(総合一覧!$B$2:$B$6943,A8,総合一覧!$M$2:$M$6943),1) | D8: =_xlfn.MAXIFS(総合一覧!$M$2:$M$6943,総合一覧!$B$2:$B$6943,A8) | E8: =COUNTIFS(総合一覧!$B$2:$B$6943,A8,総合一覧!$M$2:$M$6943,">=70")
A9: GitHub | B9: =COUNTIF(総合一覧!$B$2:$B$6943,A9) | C9: =ROUND(AVERAGEIF(総合一覧!$B$2:$B$6943,A9,総合一覧!$M$2:$M$6943),1) | D9: =_xlfn.MAXIFS(総合一覧!$M$2:$M$6943,総合一覧!$B$2:$B$6943,A9) | E9: =COUNTIFS(総合一覧!$B$2:$B$6943,A9,総合一覧!$M$2:$M$6943,">=70")
A10: 合計 | B10: =SUM(B2:B9) | C10: =ROUND(AVERAGE(総合一覧!$M$2:$M$6943),1) | D10: =MAX(総合一覧!$M$2:$M$6943) | E10: =SUM(E2:E9)
A12: ※地域ごとに別々のAIが採点したため、地域間で点数の付け方に多少のばらつきがあります（例: 中国語圏はやや高め）。

Sheet 採点基準
A1: 採点基準（各25点満点・合計100点）
A3: 項目 | B3: 内容 | C3: 高得点（22〜25点） | D3: 低得点（0〜7点）
A4: 非代替性 | B4: 今のAutoCAD（2024〜2026、Express Tools含む）の標準機能で代わりがきかないか | C4: 標準機能では実現できない | D4: 標準機能（COUNT、TEXTALIGN、BURST、OVERKILL等）でほぼ同じことができる
A5: 斬新さ | B5: 発想の面白さ・目新しさ | C5: 「その手があったか」という発想（自動更新、動的プレビュー、コマンド連動など） | D5: 単純な設定変更や標準コマンドの言い換え
A6: 時短効果 | B6: 1回あたりの時短 × 使う頻度 | C6: よく使う作業で数分〜数時間を短縮（一括処理・自動集計・自動連番など） | D6: 数回のキー操作分の短縮、関数部品、ゲーム
A7: 汎用性 | B7: どんな図面でも使えるか | C7: ほぼすべての図面で使える（文字・画層・ブロック・一括処理・印刷） | D7: 特定の国の規格・特定製品・特定分野専用
A9: 注記
A10: ・採点はコマンドの説明文をもとにしたAIによる評価で、実際に動かして確認したものではありません。
A11: ・対象: 全地域（英語圏・日本・中国語圏・ロシア語圏・ベトナム/東南アジア・ヨーロッパ・その他・GitHub）。同じ名前・同じコマンドの重複は、点数の高い1件にまとめ「同じツールの別掲載」列に他の掲載先を記載。調査日 2026-09-26〜27。
A12: ・「LISP開発用の部品」はコマンドではなくプログラム内で使う関数のため、時短効果は最大7点としています。
A13: ・点数は「一覧」シートで直接書き換えられます（合計と順位は自動で再計算されます）。
